<?xml version="1.0" ?>
<!-- =================================================================================== -->
<!-- |    This document was autogenerated by xacro from panda_arm_hand.urdf.xacro      | -->
<!-- |    EDITING THIS FILE BY HAND IS NOT RECOMMENDED                                 | -->
<!-- =================================================================================== -->
<robot name="panda" xmlns:xacro="http://www.ros.org/wiki/xacro">
  <link name="panda_link0">
  	<inertial>
      <origin rpy="0 0 0" xyz="-0.0172 0.0004 0.0745"/>
       <mass value="2.3966"/>
           <inertia ixx="0.0090" ixy="0.0000" ixz="0.0020"
               iyy="0.0115" iyz="0.0000" izz="0.0085"/>
    </inertial>
    <collision>
      <geometry>
        <mesh filename="meshes/franka/link0.stl"/>
      </geometry>
    </collision>
  </link>
  <link name="panda_link1">
      <inertial>
      <origin xyz="0.0000004128 -0.0181251324 -0.0386035970" rpy="0 0 0"/>
      <mass value="2.9274653454"/>
      <inertia ixx="0.023927316485107913" ixy="1.3317903455714081e-05" ixz="-0.00011404774918616684"
               iyy="0.0224821613275756" iyz="-0.0019950320628240115" izz="0.006350098258530016"/>
    </inertial>
    <collision>
      <geometry>
        <mesh filename="meshes/franka/link1.stl"/>
      </geometry>
    </collision>
  </link>
  <joint name="panda_joint1" type="revolute">
    <safety_controller k_position="100.0" k_velocity="40.0" soft_lower_limit="-2.8973" soft_upper_limit="2.8973"/>
    <origin rpy="0 0 0" xyz="0 0 0.333"/>
    <parent link="panda_link0"/>
    <child link="panda_link1"/>
    <axis xyz="0 0 1"/>
    <limit effort="87" lower="-2.9671" upper="2.9671" velocity="2.1750"/>
  </joint>
  <link name="panda_link2">
      <inertial>
      <origin xyz="0.0031828864 -0.0743221644 0.0088146084" rpy="0 0 0"/>
      <mass value="2.9355370338"/>
      <inertia ixx="0.041938946257609425" ixy="0.00020257331521090626" ixz="0.004077784227179924"
               iyy="0.02514514885014724" iyz="-0.0042252158006570156" izz="0.06170214472888839"/>
    </inertial>
    <collision>
      <geometry>
        <mesh filename="meshes/franka/link2.stl"/>
      </geometry>
    </collision>
  </link>
  <joint name="panda_joint2" type="revolute">
    <safety_controller k_position="100.0" k_velocity="40.0" soft_lower_limit="-1.7628" soft_upper_limit="1.7628"/>
    <origin rpy="-1.57079632679 0 0" xyz="0 0 0"/>
    <parent link="panda_link1"/>
    <child link="panda_link2"/>
    <axis xyz="0 0 1"/>
    <limit effort="87" lower="-1.8326" upper="1.8326" velocity="2.1750"/>
  </joint>
  <link name="panda_link3">
      <inertial>
      <origin xyz="0.0407015686 -0.0048200565 -0.0289730823" rpy="0 0 0"/>
      <mass value="2.2449013699"/>
      <inertia ixx="0.02410142547240885" ixy="0.002404694559042109" ixz="-0.002856269270114313"
               iyy="0.01974053266708178" iyz="-0.002104212683891874" izz="0.019044494482244823"/>
    </inertial>
    <collision>
      <geometry>
        <mesh filename="meshes/franka/link3.stl"/>
      </geometry>
    </collision>
  </link>
  <joint name="panda_joint3" type="revolute">
    <safety_controller k_position="100.0" k_velocity="40.0" soft_lower_limit="-2.8973" soft_upper_limit="2.8973"/>
    <origin rpy="1.57079632679 0 0" xyz="0 -0.316 0"/>
    <parent link="panda_link2"/>
    <child link="panda_link3"/>
    <axis xyz="0 0 1"/>
    <limit effort="87" lower="-2.9671" upper="2.9671" velocity="2.1750"/>
  </joint>
  <link name="panda_link4">
      <inertial>
      <origin xyz="-0.0459100965 0.0630492960 -0.0085187868" rpy="0 0 0"/>
      <mass value="2.6155955791"/>
      <inertia ixx="0.03452998321913202" ixy="0.01322552265982813" ixz="0.01015142998484113"
               iyy="0.028881621933049058" iyz="-0.0009762833870704552" izz="0.04125471171146641"/>
    </inertial>
    <collision>
      <geometry>
        <mesh filename="meshes/franka/link4.stl"/>
      </geometry>
    </collision>
  </link>
  <joint name="panda_joint4" type="revolute">
    <safety_controller k_position="100.0" k_velocity="40.0" soft_lower_limit="-3.0718" soft_upper_limit="-0.0698"/>
    <origin rpy="1.57079632679 0 0" xyz="0.0825 0 0"/>
    <parent link="panda_link3"/>
    <child link="panda_link4"/>
    <axis xyz="0 0 1"/>
    <limit effort="87" lower="-3.1416" upper="0.0" velocity="2.1750"/>
  </joint>
  <link name="panda_link5">
      <inertial>
      <origin xyz="-0.0016039605 0.0292536262 -0.0972965990" rpy="0 0 0"/>
      <mass value="2.3271207594"/>
      <inertia ixx="0.051610278463662895" ixy="-0.005715173387783472" ixz="-0.0035673167625872135"
               iyy="0.04787729713371481" iyz="0.010673985108535986" izz="0.016423625579357254"/>
    </inertial>
    <collision>
      <geometry>
        <mesh filename="meshes/franka/link5.stl"/>
      </geometry>
      <material name="panda_white"/>
    </collision>
  </link>
  <joint name="panda_joint5" type="revolute">
    <safety_controller k_position="100.0" k_velocity="40.0" soft_lower_limit="-2.8973" soft_upper_limit="2.8973"/>
    <origin rpy="-1.57079632679 0 0" xyz="-0.0825 0.384 0"/>
    <parent link="panda_link4"/>
    <child link="panda_link5"/>
    <axis xyz="0 0 1"/>
    <limit effort="12" lower="-2.9671" upper="2.9671" velocity="2.6100"/>
  </joint>
  <link name="panda_link6">
      <inertial>
      <origin xyz="0.0597131221 -0.0410294666 -0.0101692726" rpy="0 0 0"/>
      <mass value="1.8170376524"/>
      <inertia ixx="0.005412333594383447" ixy="0.006193456360285834" ixz="0.0014219289306117652"
               iyy="0.014058329545509979" iyz="-0.0013140753741120031" izz="0.016080817924212554"/>
    </inertial>
    <collision>
      <geometry>
        <mesh filename="meshes/franka/link6.stl"/>
      </geometry>
      <material name="panda_white"/>
    </collision>
  </link>
  <joint name="panda_joint6" type="revolute">
    <safety_controller k_position="100.0" k_velocity="40.0" soft_lower_limit="-0.0175" soft_upper_limit="3.7525"/>
    <origin rpy="1.57079632679 0 0" xyz="0 0 0"/>
    <parent link="panda_link5"/>
    <child link="panda_link6"/>
    <axis xyz="0 0 1"/>
    <limit effort="12" lower="-0.0873" upper="3.8223" velocity="2.6100"/>
  </joint>
  <link name="panda_link7">
      <inertial>
      <origin xyz="0.0045225817 0.0086261921 -0.0161633251" rpy="0 0 0"/>
      <mass value="0.6271432862"/>
      <inertia ixx="0.00021092389150104718" ixy="-2.433299114461931e-05" ixz="4.564480393778983e-05"
               iyy="0.00017718568002411474" iyz="8.744070223226438e-05" izz="5.993190599659971e-05"/>
    </inertial>
    <collision>
      <geometry>
        <mesh filename="meshes/franka/link7.stl"/>
      </geometry>
    </collision>
  </link>
  <joint name="panda_joint7" type="revolute">
    <safety_controller k_position="100.0" k_velocity="40.0" soft_lower_limit="-2.8973" soft_upper_limit="2.8973"/>
    <origin rpy="1.57079632679 0 0" xyz="0.088 0 0"/>
    <parent link="panda_link6"/>
    <child link="panda_link7"/>
    <axis xyz="0 0 1"/>
    <limit effort="12" lower="-2.9671" upper="2.9671" velocity="2.6100"/>
  </joint>

  <link name="panda_link8">
  	 <inertial>
      <origin rpy="0 0 0" xyz="0 0 0"/>
       <mass value="0.0001"/>
       <inertia ixx="0.1" ixy="0" ixz="0" iyy="0.1" iyz="0" izz="0.1"/>
    </inertial>
  </link>

  <joint name="panda_joint8" type="fixed">
    <origin rpy="0 0 0" xyz="0 0 0.107"/>
    <parent link="panda_link7"/>
    <child link="panda_link8"/>
    <axis xyz="0 0 0"/>
  </joint>


  <link name="panda_hand">
  	<inertial>
      <origin rpy="0 0 0" xyz="-0.01 0 0.03"/>
       <mass value=".73"/>
       <inertia ixx="0.001" ixy="0" ixz="0" iyy="0.0025" iyz="0" izz="0.0017"/>
    </inertial>
    <collision>
      <geometry>
        <mesh filename="meshes/franka/hand.stl"/>
      </geometry>
    </collision>
  </link>

  <joint name="panda_hand_joint" type="fixed">
    <parent link="panda_link8"/>
    <child link="panda_hand"/>
    <origin rpy="0 0 -0.785398163397" xyz="0 0 0"/>
  </joint>

  <link name="panda_leftfinger">
  	<inertial>
      <origin rpy="0 0 0" xyz="0 0.0 0.0"/>
       <mass value="0.015"/>
       <inertia ixx="2.3749999999999997e-06" ixy="0" ixz="0" iyy="2.3749999999999997e-06" iyz="0" izz="7.5e-07"/>
    </inertial>
    <collision>
      <geometry>
        <mesh filename="meshes/franka/finger.stl"/>
      </geometry>
    </collision>
  </link>

  <link name="panda_rightfinger">
  	<inertial>
      <origin rpy="0 0 0" xyz="0 0.0 0.0"/>
       <mass value="0.015"/>
       <inertia ixx="2.3749999999999997e-06" ixy="0" ixz="0" iyy="2.3749999999999997e-06" iyz="0" izz="7.5e-07"/>
    </inertial>
    <collision>
      <origin rpy="0 0 3.14159265359" xyz="0 0 0"/>
      <geometry>
        <mesh filename="meshes/franka/finger.stl"/>
      </geometry>
    </collision>
  </link>

  <joint name="panda_finger_joint1" type="prismatic">
    <parent link="panda_hand"/>
    <child link="panda_leftfinger"/>
    <origin rpy="0 0 0" xyz="0 0 0.0584"/>
    <axis xyz="0 1 0"/>
    <limit effort="20" lower="0.0" upper="0.04" velocity="0.2"/>
  </joint>

  <joint name="panda_finger_joint2" type="prismatic">
    <parent link="panda_hand"/>
    <child link="panda_rightfinger"/>
    <origin rpy="0 0 0" xyz="0 0 0.0584"/>
    <axis xyz="0 -1 0"/>
    <limit effort="20" lower="0.0" upper="0.04" velocity="0.2"/>
    <mimic joint="panda_finger_joint1"/>
  </joint>

  <link name="panda_pusher">
    <collision>
      <geometry>
        <mesh filename="meshes/franka/pusher.stl"/>
      </geometry>
    </collision>
  	<inertial>
      <origin rpy="0 0 0" xyz="0 0.0 0.0"/>
       <mass value="0.02916"/>
       <inertia ixx="0.00006078" ixy="0" ixz="0" iyy="0.00006066" iyz="0" izz="0.00000259"/>
    </inertial>
  </link>

  <joint name="panda_pusher_joint" type="fixed">
    <parent link="panda_hand"/>
    <child link="panda_pusher"/>
    <origin rpy="0 3.14159265359 0" xyz="0 0.00 0.108"/>
  </joint>
  
</robot>